Workbook

Sheet User Input
G6: ELEVATED WATER TOWER | L6: LIT-03 | W6: LIT-02 | Y6: FIT-105
M7: % | U7: CLEARWELL | X7: % | Z7: L/s
H9: Baffling | J9: 0.1
B10: FRC-01 | E10: TEM-01 | M10: FRC-02 | P10: FIT-102
C11: mg/L | F11: oC | N11: mg/L | Q11: L/s
M12: PH-02
B13: FIT-106 | E13: PH-03
C14: L/s
B16: TO DISTRIBUTION | U16: Baffling | W16: 0.1
R18: A Filtration Credit can been applied for use in calculating total reduction of Giardia and Viruses. In order to be considered conventional filtration and claim the 2.5 log Giardia cyst removal and 2 log virus removal credit, the filtration process must meet the following criteria: * use a chemical coagulant at all times when the treatment plant is in operation; * monitor and adjust chemical dosages in response to variations in raw water quality; * maintain effective backwash procedures, including filter-to-waste or an equivalent procedure during filter ripening to ensure that the effluent turbidity requirements are met at all times; * continuously monitor filtrate turbidity from each filter; and * meet the performance criterion for filtered water turbidity of less than or equal to 0.3 NTU in 95% of the measurements each month. When this Filtration Credit is being met, the target Log-Inactivation for this CT Calculator is 0.5 for Giardia, and 2 for Viruses.
C19: Summary of Inactivation Credits | N19: Target Log-Inactivation
H20: Giardia | I20: Viruses | N20: Giardia | P20: 0.5
C21: CT Achieved | H21: =Calculations!C26 -> #DIV/0! | I21: =Calculations!D26 -> #DIV/0! | N21: Viruses | P21: 2
C22: CT Required | H22: =Calculations!C27 -> #DIV/0! | I22: =Calculations!D27 -> #DIV/0!
C23: Log Inactivation | H23: =IF(Calculations!C24>3,"> 3",Calculations!C24) -> #VALUE! | I23: =IF(Calculations!D24>4,"> 4",Calculations!D24) -> #DIV/0!

Sheet Release Notes
A1: Release Notes for Niagara Falls CT Calculator Version 1.1
B3: These notes are best viewed by printing them out and referring to them while using the program.
B4: Developers, please update these notes by adding to them with each new release of the program.
B5: Users, you can add notes at the bottom of the list, however existing notes will be locked for editing.
G6: User Note | H6: Developer Note | I6: Name | J6: Date
A7: 1 | B7: When the program loads, all toolbars except Standard and Formatting are cleared from view. Scroll is locked so that the user cannot view any cells outside the screen area. The user input screen is best viewed at a resolution of 1024x768. The zoom has not been locked, however, it is not guaranteed that all cells will be visible if the user chooses to zoom out. It is best viewed at 100%. | I7: N. Sherwood | J7: 38895
A9: 2 | B9: All cells are locked for editing except green marked cells. These cells are for the user to input data. | I9: N. Sherwood | J9: 38895
C10: Input
C11: Output
A13: 2.1 | B13: Cells with check boxes are automatically locked and grayed out when the check box is unchecked. To input a value, the user must first check the box. | I13: N. Sherwood | J13: 38895
A15: 3.1 | B15: All inputs are limited to decimal or integer values. The following is a list of restrictions placed on each input: | I15: N. Sherwood | J15: 39871
C16: Must be between:
B17: Decay constant k: | C17: 0 | E17: 0.01 | F17: *based on normal operating procedures
B18: Giardia setpoint | C18: 0 | E18: 3 | F18: *see note 4
B19: Virus setpoint | C19: 0 | E19: 4 | F19: *see note 4
B20: Chlorine concentration | C20: 0 | E20: 5 | F20: *based on normal operating procedures
B21: Temperature | C21: 0.5 | D21: and | E21: 25 | F21: *based on table values
B22: pH | C22: 6.51 | E22: 9 | F22: *based on table values
B23: Backwash Frequency | C23: 0 | E23: 8 | F23: *based on normal operating procedures
B24: Reservoir level (% Full) | C24: 0 | E24: 100
B25: Baffle factor | C25: 0 | E25: 1
B26: The program will warn the user if a value they have entered is outside these restrictions. There is no restriction on the input for flow (except that it can't be negative). | I26: N. Sherwood | J26: 38895
A28: 3.2 | B28: Since there are multiple inputs for pH and temperature, the program uses the minimum of each of these inputs for the calculation. For pH, the values are rounded up to the nearest integer, and for temperature, the values are rounded down to the nearest 5°C. | I28: N. Sherwood | J28: 38895
A30: 3.3 | B30: Top water level (TWL) of 5 m was used for the Reservoir because none was provided in drawing set. It is assumed that the bottom of the reservoir is at elevation 170.000 by averaging the variations in the slope of the reservoir floor, and the maximum TWL is 175. This was based on Drawing S401 from contract 03-10. This gives a conservative estimation of maximum reservoir volume of 13,100 m3 (CofA states that the reservoir volume is 14 ML). | I30: N. Sherwood | J30: 39871
A32: 3.4 | B32: Recommended baffle factor of 0.5 has been set for the Reservoir. This is based on calculations done previously at the plant, and on the volumes calculated based on the drawing set for contract 03-10. | I32: N. Sherwood | J32: 39871
A34: 4 | B34: Output values for log removal credits are not shown if they exceed 3 or 4-log removal respectively. This is because the disinfection tables do not provide information for CT values beyond 3 and 4-log removal. | I34: N. Sherwood | J34: 38895
A36: 5 | B36: Pre-filtration credits are not being considered at this time. Since GAC is used in the filters, any pre-chlorination residual will likely be 0 at the filter effluent. In addition, at the time of publication, the MOE did not permit pre-filtration to be used for disinfection credit. | I36: N. Sherwood | J36: 38895
A38: 6.1 | B38: It is assumed that Clearwell 1 and Clearwell 2 cannot be taken for credit. This is because the main injection points for chlorine are located downstream of the clearwells. | I38: N. Sherwood | J38: 39871
A40: 6.2 | B40: It is assumed that the Clearwells are run in series (CW 1, then CW 2, then UV). | I40: N. Sherwood | J40: 38895
A42: 7 | B42: The flow meters in the UV building are summed in the calculations for flow into the Reservoir. The sum of the flow to the distribution system is used as the flow out of the Reservoir. | I42: N. Sherwood | J42: 38895
A44: 8 | B44: Setting the flow to zero for any of the UV reactors means that you are shutting the valve for that reactor. Do not set all of the flow in the UV building to zero, this indicates that no flow is getting to the Reservoir, and that no flow is leaving the Clearwells. The plant cannot run for long in this configuration, as the Reservoir will empty, and the Clearwells will overflow. | I44: N. Sherwood | J44: 38895
A46: 8.1 | B46: UV disinfection is based on the lowest dosage (in mJ/cm2) of the UV reactors. Therefore, by setting one of the dosages to zero, it is the same as turning off all the reactors (but not the flow). However, if the flow is set to zero for any of the UV reactors, the adjoining dose no longer affects the calculation. | I46: N. Sherwood | J46: 38895
A48: 8.2 | B48: UV credit is applied separate from the Disinfection Credits. The current C of A for the plant states: "an Ultraviolet Primary Disinfection System consisting of five (5) UV reactors (four duty, one standby) installed downstream of the existing clearwells in a new UV disinfection Building, designed to provide a minimum disinfection dose of 40 mJ/cm2 at 254 nm at the end of lamp life and at a UV transmittance of 90% for the maximum flow rate of 1736 L/s (150 ML/d) and provide a minimum 3-log inactivation of Giardia." So if the CT Calculator detects a dosage below 40 mJ/cm2, no credit will be applied, and the cells will turn red. | I48: N. Sherwood | J48: 39871
A50: 9 | B50: A Safety Factor has been included for each distribution point to provide the operator with a representation of the realtime factor of safety that is being implemented at current measurements of pH, temperature, flow, and chlorine residual. The Safety Factor will turn red (alarm) when it drops below 1.2. A Safety Factor of less than 1 means the plant is running out of compliance. | I50: N. Sherwood | J50: 38895
... A72: 99.1 | B72: Version 1.1 changes made to match PLC CT calculator provided for Region. Changes are dated 2/27/2009. | I72: N. Sherwood | J72: 39871

Sheet Calculations
A1: Segment | B1: Description | C1: Volume | D1: Flow | E1: HDT | F1: Baffle | G1: T10 | H1: pH | I1: round | J1: Co | K1: round | L1: Temp | M1: round | N1: Giardia | O1: Log | P1: Log | R1: Virus | S1: Log | T1: Log
C2: m3 | D2: L/s | E2: min | G2: min | I2: up | J2: mg/L | K2: up | L2: °C | M2: down | N2: k | O2: eqn 1 | P2: eqn 2 | Q2: max | R2: k | S2: eqn 1 | T2: eqn 2 | U2: max
A3: 1 | B3: River Intake Pipe
A4: 2 | B4: Raw Water Well
A5: 3
A6: 21
A7: 22 | B7: Pipe to Clearwell | D7: ='User Input'!Y7 -> 0 | F7: 1
A8: 23 | B8: Clearwell | C8: =I23*'User Input'!W7/100 -> 0 | D8: =MAX('User Input'!Y7,'User Input'!P11) -> 0 | E8: =IF(C8>0, C8/D8*1000/60,0) -> 0 | F8: ='User Input'!W16 -> 0.1 | G8: =E8*F8 -> 0 | H8: ='User Input'!M13 -> 0 | I8: =CEILING(H8,0.5) -> 0 | J8: ='User Input'!M11 -> 0 | K8: =IF(J8<0,0,CEILING(J8,0.2)) -> 0 | L8: ='User Input'!$E$11 -> 0 | M8: =IF(L8<5,0.5,FLOOR(L8,5)) -> 0.5 | N8: =VLOOKUP(K8,'Giardia CT'!$S$4:$X$18,2*I8-12) -> #VALUE! | O8: =N8*J8*G8 -> #VALUE! | P8: =IF(J8=0,0,J8*G8/(0.2828*H8^2.69*J8^0.15*0.933^(L8-5))) -> 0 | Q8: =MAX(O8:P8) -> #VALUE! | R8: =IF(K8=0, 0,VLOOKUP(M8,'Virus CT'!$H$6:$I$11,2)) -> 0 | S8: =R8*J8*G8 -> 0 | T8: =IF(J8=0,0,(J8*G8*EXP(0.071*M8)-0.42)/2.94) -> 0 | U8: =MAX(S8:T8) -> 0
A9: 24 | B9: Pipe CW to Tower | C9: =$I$24 -> 23.561945 | D9: ='User Input'!$P$11 -> 0 | E9: =IF(C9>0, C9/D9*1000/60,0) -> #DIV/0! | F9: 1 | G9: =E9*F9 -> #DIV/0! | H9: ='User Input'!M13 -> 0 | I9: =CEILING(H9,0.5) -> 0 | J9: ='User Input'!M11 -> 0 | K9: =IF(J9<0,0,CEILING(J9,0.2)) -> 0 | L9: ='User Input'!$E$11 -> 0 | M9: =IF(L9<5,0.5,FLOOR(L9,5)) -> 0.5 | N9: =VLOOKUP(K9,'Giardia CT'!$S$4:$X$18,2*I9-12) -> #VALUE! | O9: =N9*J9*G9 -> #VALUE! | P9: =IF(J9=0,0,J9*G9/(0.2828*H9^2.69*J9^0.15*0.933^(L9-5))) -> 0 | Q9: =MAX(O9:P9) -> #VALUE! | R9: =IF(K9=0, 0,VLOOKUP(M9,'Virus CT'!$H$6:$I$11,2)) -> 0 | S9: =R9*J9*G9 -> #DIV/0! | T9: =IF(J9=0,0,(J9*G9*EXP(0.071*M9)-0.42)/2.94) -> 0 | U9: =MAX(S9:T9) -> #DIV/0!
A10: 25 | B10: Tower | C10: =I25*'User Input'!L7/100+300 -> 300 | D10: =MAX('User Input'!P11,'User Input'!B14) -> 0 | E10: =IF(C10>0, C10/D10*1000/60,0) -> #DIV/0! | F10: ='User Input'!J9 -> 0.1 | G10: =E10*F10 -> #DIV/0! | H10: ='User Input'!E14 -> 0 | I10: =CEILING(H10,0.5) -> 0 | J10: ='User Input'!B11 -> 0 | K10: =IF(J10<0,0,CEILING(J10,0.2)) -> 0 | L10: ='User Input'!$E$11 -> 0 | M10: =IF(L10<5,0.5,FLOOR(L10,5)) -> 0.5 | N10: =VLOOKUP(K10,'Giardia CT'!$S$4:$X$18,2*I10-12) -> #VALUE! | O10: =N10*J10*G10 -> #VALUE! | P10: =IF(J10=0,0,J10*G10/(0.2828*H10^2.69*J10^0.15*0.933^(L10-5))) -> 0 | Q10: =MAX(O10:P10) -> #VALUE! | R10: =IF(K10=0, 0,VLOOKUP(M10,'Virus CT'!$H$6:$I$11,2)) -> 0 | S10: =R10*J10*G10 -> #DIV/0! | T10: =IF(J10=0,0,(J10*G10*EXP(0.071*M10)-0.42)/2.94) -> 0 | U10: =MAX(S10:T10) -> #DIV/0!
A11: 26 | B11: Pipe Tower to 1st User | D11: ='User Input'!B14 -> 0 | F11: 1 | G11: =E11*F11 -> 0 | H11: ='User Input'!E14 -> 0 | I11: =CEILING(H11,0.5) -> 0 | J11: ='User Input'!B11 -> 0 | K11: =IF(J11<0,0,CEILING(J11,0.2)) -> 0 | L11: ='User Input'!$E$11 -> 0 | M11: =IF(L11<5,0.5,FLOOR(L11,5)) -> 0.5 | N11: =VLOOKUP(K11,'Giardia CT'!$S$4:$X$18,2*I11-12) -> #VALUE! | Q11: =MAX(O11:P11) -> 0 | R11: =IF(K11=0, 0,VLOOKUP(M11,'Virus CT'!$H$6:$I$11,2)) -> 0 | U11: =MAX(S11:T11) -> 0
B14: 1-Hour Forecast
B15: Clearwell | C15: =MIN(C8+(D7-D9)*3600*4/1000,100) -> 0 | D15: =D8 -> 0 | E15: =IF(C15>0, C15/D15*1000/60,0) -> 0 | F15: 0.1 | G15: =E15*F15 -> 0 | H15: =H8 -> 0 | I15: =CEILING(H15,0.5) -> 0 | J15: =J8 -> 0 | K15: =K9 -> 0 | L15: =L9 -> 0 | M15: =M9 -> 0.5 | N15: =VLOOKUP(K15,'Giardia CT'!$S$4:$X$18,2*I15-12) -> #VALUE! | O15: =N15*J15*G15 -> #VALUE! | P15: =IF(J15=0,0,J15*G15/(0.2828*H15^2.69*J15^0.15*0.933^(L15-5))) -> 0 | Q15: =MAX(O15:P15) -> #VALUE! | R15: =IF(K15=0, 0,VLOOKUP(M15,'Virus CT'!$H$6:$I$11,2)) -> 0 | S15: =R15*J15*G15 -> 0 | T15: =IF(J15=0,0,(J15*G15*EXP(0.071*L15)-0.42)/2.94) -> 0 | U15: =MAX(S15:T15) -> 0
A16: 24 | B16: Pipe CW to Tower | C16: =$I$24 -> 23.561945 | D16: =D9 -> 0 | E16: =IF(C16>0, C16/D16*1000/60,0) -> #DIV/0! | F16: 1 | G16: =E16*F16 -> #DIV/0! | H16: =H9 -> 0 | I16: =CEILING(H16,0.5) -> 0 | J16: =J9 -> 0 | K16: =IF(J16<0,0,CEILING(J16,0.2)) -> 0 | L16: ='User Input'!$E$11 -> 0 | M16: =IF(L16<5,0.5,FLOOR(L16,5)) -> 0.5 | N16: =VLOOKUP(K16,'Giardia CT'!$S$4:$X$18,2*I16-12) -> #VALUE! | O16: =N16*J16*G16 -> #VALUE! | P16: =IF(J16=0,0,J16*G16/(0.2828*H16^2.69*J16^0.15*0.933^(L16-5))) -> 0 | Q16: =MAX(O16:P16) -> #VALUE! | R16: =IF(K16=0, 0,VLOOKUP(M16,'Virus CT'!$H$6:$I$11,2)) -> 0 | S16: =R16*J16*G16 -> #DIV/0! | T16: =IF(J16=0,0,(J16*G16*EXP(0.071*L16)-0.42)/2.94) -> 0 | U16: =MAX(S16:T16) -> #DIV/0!
B17: Tower | C17: =MIN(C10+(D9-D11)*3600*4/1000,1300) -> 300 | D17: =D10 -> 0 | E17: =IF(C17>0, C17/D17*1000/60,0) -> #DIV/0! | F17: 0.1 | G17: =E17*F17 -> #DIV/0! | H17: =H10 -> 0 | I17: =CEILING(H17,0.5) -> 0 | J17: =J10 -> 0 | K17: =K10 -> 0 | L17: =L10 -> 0 | M17: =M10 -> 0.5 | N17: =VLOOKUP(K17,'Giardia CT'!$S$4:$X$18,2*I17-12) -> #VALUE! | O17: =N17*J17*G17 -> #VALUE! | P17: =IF(J17=0,0,J17*G17/(0.2828*H17^2.69*J17^0.15*0.933^(L17-5))) -> 0 | Q17: =MAX(O17:P17) -> #VALUE! | R17: =IF(K17=0, 0,VLOOKUP(M17,'Virus CT'!$H$6:$I$11,2)) -> 0 | S17: =R17*J17*G17 -> #DIV/0! | T17: =IF(J17=0,0,(J17*G17*EXP(0.071*L17)-0.42)/2.94) -> 0 | U17: =MAX(S17:T17) -> #DIV/0!
B21: Summary of Inactivation Credits
C22: Log Inactivation | F22: Volumes
B23: Component | C23: Giardia | D23: Virsuses | F23: Clearwell | I23: 100 | M23: Log Eqn 2 Formulas:
B24: Chlorine | C24: =SUM(Q8:Q10) -> #VALUE! | D24: =SUM(U8:U10) -> #DIV/0! | F24: Pipe from CW to Tower | I24: 23.561945 | M24: Giardia | N24: Log-reduction = CT Actual / [0.2828 x (pH)^2.69 x (Free Cl Conc.)^0.15 x 0.933^(Temp. - 5)]
B25: 4 Hr Forecast (Cl Only) | C25: =SUM(Q15:Q17) -> #VALUE! | D25: =SUM(U15:U17) -> #DIV/0! | F25: Tower | I25: 1000 | M25: Viruses | N25: Log-reduction = {[CT Actual x e^(0.071 x Temp.)] - 0.42} / 2.94
B26: CT Achieved | C26: =J8*G8+J9*G9+J10*G10 -> #DIV/0! | D26: =C26 -> #DIV/0!
B27: CT Required | C27: =C26*'User Input'!P20/C24 -> #DIV/0! | D27: =D26*'User Input'!P21/D24 -> #DIV/0!

Sheet Giardia CT
A1: CT Tables | H1: Giardia Cysts | S1: Temperature 1: | T1: =IF('User Input'!E11<0.5,0.5,'User Input'!E11) -> 0.5 | U1: oC
H2: Average K values for every temp, pH | S2: Giardia k Table | T2: pH
A3: Giardia Cysts | H3: Cf | I3: k | J3: Cf | K3: k | L3: Cf | M3: k | N3: Cf | O3: k | P3: Cf | Q3: k | S3: Co | T3: 7 | U3: 7.5 | V3: 8 | W3: 8.5 | X3: 9
A4: Temp | B4: pH | C4: Free Cl2 Conc | D4: log inactivation | E4: CT | F4: k | G4: temp: | I4: 0.5 | K4: 5 | M4: 10 | O4: 15 | Q4: 20 | S4: 0 | T4: 0 | U4: 0 | V4: 0 | W4: 0 | X4: 0
A5: 0.5 | B5: 7 | C5: 0.4 | D5: 0.5 | E5: 33 | F5: =D5/E5 -> 0.015151515 | G5: pH: | I5: 7 | K5: 7 | M5: 7 | O5: 7 | Q5: 7 | S5: 0.4 | T5: =HLOOKUP($T$1,$I$4:$Q$19,$Y5) -> 0.015324818 | U5: =HLOOKUP($T$1,$I$20:$Q$35,$Y5) -> 0.012617665 | V5: =HLOOKUP($T$1,$I$36:$Q$51,$Y5) -> 0.010832357 | W5: =HLOOKUP($T$1,$I$52:$Q$67,$Y5) -> 0.0091079627 | X5: =HLOOKUP($T$1,$I$68:$Q$83,$Y5) -> 0.0076923077 | Y5: 3
A6: 0.5 | B6: 7 | C6: 0.4 | D6: 1 | E6: 65 | F6: =D6/E6 -> 0.015384615 | H6: 0.4 | I6: =AVERAGE(F5:F10) -> 0.015324818 | J6: 0.4 | K6: =AVERAGE(F341:F346) -> 0.021591111 | L6: 0.4 | M6: =AVERAGE(F677:F682) -> 0.02889944 | N6: 0.4 | O6: =AVERAGE(F1013:F1018) -> 0.042752642 | P6: 0.4 | Q6: =AVERAGE(F1349:F1354) -> 0.057507682 | S6: 0.6 | T6: =HLOOKUP($T$1,$I$4:$Q$19,$Y6) -> 0.01501409 | U6: =HLOOKUP($T$1,$I$20:$Q$35,$Y6) -> 0.012532289 | V6: =HLOOKUP($T$1,$I$36:$Q$51,$Y6) -> 0.010482902 | W6: =HLOOKUP($T$1,$I$52:$Q$67,$Y6) -> 0.0087719298 | X6: =HLOOKUP($T$1,$I$68:$Q$83,$Y6) -> 0.0073640893 | Y6: 4
A7: 0.5 | B7: 7 | C7: 0.4 | D7: 1.5 | E7: 98 | F7: =D7/E7 -> 0.015306122 | H7: 0.6 | I7: =AVERAGE(F11:F16) -> 0.01501409 | J7: 0.6 | K7: =AVERAGE(F347:F352) -> 0.020923343 | L7: 0.6 | M7: =AVERAGE(F683:F687) -> 0.027918447 | N7: 0.6 | O7: =AVERAGE(F1019:F1024) -> 0.041666667 | P7: 0.6 | Q7: =AVERAGE(F1355:F1360) -> 0.055555556 | S7: 0.8 | T7: =HLOOKUP($T$1,$I$4:$Q$19,$Y7) -> 0.014637907 | U7: =HLOOKUP($T$1,$I$20:$Q$35,$Y7) -> 0.012195122 | V7: =HLOOKUP($T$1,$I$36:$Q$51,$Y7) -> 0.010171279 | W7: =HLOOKUP($T$1,$I$52:$Q$67,$Y7) -> 0.0084745763 | X7: =HLOOKUP($T$1,$I$68:$Q$83,$Y7) -> 0.0071121293 | Y7: 5
A8: 0.5 | B8: 7 | C8: 0.4 | D8: 2 | E8: 130 | F8: =D8/E8 -> 0.015384615 | H8: 0.8 | I8: =AVERAGE(F17:F22) -> 0.014637907 | J8: 0.8 | K8: =AVERAGE(F353:F358) -> 0.020574624 | L8: 0.8 | M8: =AVERAGE(F689:F694) -> 0.027320239 | N8: 0.8 | O8: =AVERAGE(F1025:F1030) -> 0.041128283 | P8: 0.8 | Q8: =AVERAGE(F1361:F1366) -> 0.054604979 | S8: 1 | T8: =HLOOKUP($T$1,$I$4:$Q$19,$Y8) -> 0.014285714 | U8: =HLOOKUP($T$1,$I$20:$Q$35,$Y8) -> 0.011860153 | V8: =HLOOKUP($T$1,$I$36:$Q$51,$Y8) -> 0.0098625656 | W8: =HLOOKUP($T$1,$I$52:$Q$67,$Y8) -> 0.0082105798 | X8: =HLOOKUP($T$1,$I$68:$Q$83,$Y8) -> 0.0068589863 | Y8: 6
A9: 0.5 | B9: 7 | C9: 0.4 | D9: 2.5 | E9: 163 | F9: =D9/E9 -> 0.015337423 | H9: 1 | I9: =AVERAGE(F23:F28) -> 0.014285714 | J9: 1 | K9: =AVERAGE(F359:F364) -> 0.020082923 | L9: 1 | M9: =AVERAGE(F695:F700) -> 0.026743772 | N9: 1 | O9: =AVERAGE(F1031:F1036) -> 0.03960296 | P9: 1 | Q9: =AVERAGE(F1367:F1372) -> 0.053762589 | S9: 1.2 | T9: =HLOOKUP($T$1,$I$4:$Q$19,$Y9) -> 0.013928775 | U9: =HLOOKUP($T$1,$I$20:$Q$35,$Y9) -> 0.011585342 | V9: =HLOOKUP($T$1,$I$36:$Q$51,$Y9) -> 0.0095862493 | W9: =HLOOKUP($T$1,$I$52:$Q$67,$Y9) -> 0.0079748838 | X9: =HLOOKUP($T$1,$I$68:$Q$83,$Y9) -> 0.0066526401 | Y9: 7
A10: 0.5 | B10: 7 | C10: 0.4 | D10: 3 | E10: 195 | F10: =D10/E10 -> 0.015384615 | H10: 1.2 | I10: =AVERAGE(F29:F34) -> 0.013928775 | J10: 1.2 | K10: =AVERAGE(F365:F370) -> 0.019761424 | L10: 1.2 | M10: =AVERAGE(F701:F706) -> 0.026315789 | N10: 1.2 | O10: =AVERAGE(F1037:F1042) -> 0.039384522 | P10: 1.2 | Q10: =AVERAGE(F1373:F1378) -> 0.051950368 | S10: 1.4 | T10: =HLOOKUP($T$1,$I$4:$Q$19,$Y10) -> 0.013776385 | U10: =HLOOKUP($T$1,$I$20:$Q$35,$Y10) -> 0.011286113 | V10: =HLOOKUP($T$1,$I$36:$Q$51,$Y10) -> 0.0093236285 | W10: =HLOOKUP($T$1,$I$52:$Q$67,$Y10) -> 0.0077366697 | X10: =HLOOKUP($T$1,$I$68:$Q$83,$Y10) -> 0.006468099 | Y10: 8
A11: 0.5 | B11: 7 | C11: 0.6 | D11: 0.5 | E11: 33 | F11: =D11/E11 -> 0.015151515 | H11: 1.4 | I11: =AVERAGE(F35:F40) -> 0.013776385 | J11: 1.4 | K11: =AVERAGE(F371:F376) -> 0.019307411 | L11: 1.4 | M11: =AVERAGE(F707:F712) -> 0.025904696 | N11: 1.4 | O11: =AVERAGE(F1043:F1048) -> 0.038461538 | P11: 1.4 | Q11: =AVERAGE(F1379:F1384) -> 0.051574207 | S11: 1.6 | T11: =HLOOKUP($T$1,$I$4:$Q$19,$Y11) -> 0.013263801 | U11: =HLOOKUP($T$1,$I$20:$Q$35,$Y11) -> 0.010958403 | V11: =HLOOKUP($T$1,$I$36:$Q$51,$Y11) -> 0.0091079627 | W11: =HLOOKUP($T$1,$I$52:$Q$67,$Y11) -> 0.0075576531 | X11: =HLOOKUP($T$1,$I$68:$Q$83,$Y11) -> 0.006279247 | Y11: 9
A12: 0.5 | B12: 7 | C12: 0.6 | D12: 1 | E12: 67 | F12: =D12/E12 -> 0.014925373 | H12: 1.6 | I12: =AVERAGE(F41:F46) -> 0.013263801 | J12: 1.6 | K12: =AVERAGE(F377:F382) -> 0.019010065 | L12: 1.6 | M12: =AVERAGE(F713:F718) -> 0.025129844 | N12: 1.6 | O12: =AVERAGE(F1049:F1054) -> 0.038002066 | P12: 1.6 | Q12: =AVERAGE(F1385:F1390) -> 0.050524986 | S12: 1.8 | T12: =HLOOKUP($T$1,$I$4:$Q$19,$Y12) -> 0.012944326 | U12: =HLOOKUP($T$1,$I$20:$Q$35,$Y12) -> 0.010723377 | V12: =HLOOKUP($T$1,$I$36:$Q$51,$Y12) -> 0.0088806242 | W12: =HLOOKUP($T$1,$I$52:$Q$67,$Y12) -> 0.0073640893 | X12: =HLOOKUP($T$1,$I$68:$Q$83,$Y12) -> 0.0061253948 | Y12: 10
A13: 0.5 | B13: 7 | C13: 0.6 | D13: 1.5 | E13: 100 | F13: =D13/E13 -> 0.015 | H13: 1.8 | I13: =AVERAGE(F47:F52) -> 0.012944326 | J13: 1.8 | K13: =AVERAGE(F383:F388) -> 0.018518519 | L13: 1.8 | M13: =AVERAGE(F719:F724) -> 0.024628622 | N13: 1.8 | O13: =AVERAGE(F1055:F1060) -> 0.036695911 | P13: 1.8 | Q13: =AVERAGE(F1391:F1396) -> 0.04922792 | S13: 2 | T13: =HLOOKUP($T$1,$I$4:$Q$19,$Y13) -> 0.012721946 | U13: =HLOOKUP($T$1,$I$20:$Q$35,$Y13) -> 0.010482902 | V13: =HLOOKUP($T$1,$I$36:$Q$51,$Y13) -> 0.0086659911 | W13: =HLOOKUP($T$1,$I$52:$Q$67,$Y13) -> 0.0071810887 | X13: =HLOOKUP($T$1,$I$68:$Q$83,$Y13) -> 0.0060022217 | Y13: 11
A14: 0.5 | B14: 7 | C14: 0.6 | D14: 2 | E14: 133 | F14: =D14/E14 -> 0.015037594 | H14: 2 | I14: =AVERAGE(F53:F58) -> 0.012721946 | J14: 2 | K14: =AVERAGE(F389:F394) -> 0.018098471 | L14: 2 | M14: =AVERAGE(F725:F730) -> 0.024159182 | N14: 2 | O14: =AVERAGE(F1061:F1066) -> 0.035980493 | P14: 2 | Q14: =AVERAGE(F1397:F1402) -> 0.048541775 | S14: 2.2 | T14: =HLOOKUP($T$1,$I$4:$Q$19,$Y14) -> 0.012406278 | U14: =HLOOKUP($T$1,$I$20:$Q$35,$Y14) -> 0.010075132 | V14: =HLOOKUP($T$1,$I$36:$Q$51,$Y14) -> 0.008489392 | W14: =HLOOKUP($T$1,$I$52:$Q$67,$Y14) -> 0.0070422535 | X14: =HLOOKUP($T$1,$I$68:$Q$83,$Y14) -> 0.0058714283 | Y14: 12
A15: 0.5 | B15: 7 | C15: 0.6 | D15: 2.5 | E15: 167 | F15: =D15/E15 -> 0.01497006 | H15: 2.2 | I15: =AVERAGE(F59:F64) -> 0.012406278 | J15: 2.2 | K15: =AVERAGE(F395:F400) -> 0.017757073 | L15: 2.2 | M15: =AVERAGE(F731:F736) -> 0.023632152 | N15: 2.2 | O15: =AVERAGE(F1067:F1072) -> 0.035317566 | P15: 2.2 | Q15: =AVERAGE(F1403:F1408) -> 0.047059417 | S15: 2.4 | T15: =HLOOKUP($T$1,$I$4:$Q$19,$Y15) -> 0.012148317 | U15: =HLOOKUP($T$1,$I$20:$Q$35,$Y15) -> 0.010061022 | V15: =HLOOKUP($T$1,$I$36:$Q$51,$Y15) -> 0.0083114353 | W15: =HLOOKUP($T$1,$I$52:$Q$67,$Y15) -> 0.0068844594 | X15: =HLOOKUP($T$1,$I$68:$Q$83,$Y15) -> 0.0057471264 | Y15: 13
A16: 0.5 | B16: 7 | C16: 0.6 | D16: 3 | E16: 200 | F16: =D16/E16 -> 0.015 | H16: 2.4 | I16: =AVERAGE(F65:F70) -> 0.012148317 | J16: 2.4 | K16: =AVERAGE(F401:F406) -> 0.017423797 | L16: 2.4 | M16: =AVERAGE(F737:F742) -> 0.023119964 | N16: 2.4 | O16: =AVERAGE(F1073:F1078) -> 0.034962405 | P16: 2.4 | Q16: =AVERAGE(F1409:F1414) -> 0.045887568 | S16: 2.6 | T16: =HLOOKUP($T$1,$I$4:$Q$19,$Y16) -> 0.011904762 | U16: =HLOOKUP($T$1,$I$20:$Q$35,$Y16) -> 0.0098625656 | V16: =HLOOKUP($T$1,$I$36:$Q$51,$Y16) -> 0.0081562897 | W16: =HLOOKUP($T$1,$I$52:$Q$67,$Y16) -> 0.0067567568 | X16: =HLOOKUP($T$1,$I$68:$Q$83,$Y16) -> 0.0056244806 | Y16: 14
A17: 0.5 | B17: 7 | C17: 0.8 | D17: 0.5 | E17: 34 | F17: =D17/E17 -> 0.014705882 | H17: 2.6 | I17: =AVERAGE(F71:F76) -> 0.011904762 | J17: 2.6 | K17: =AVERAGE(F407:F412) -> 0.017148063 | L17: 2.6 | M17: =AVERAGE(F743:F748) -> 0.022834478 | N17: 2.6 | O17: =AVERAGE(F1079:F1084) -> 0.034023798 | P17: 2.6 | Q17: =AVERAGE(F1415:F1420) -> 0.045454545 | S17: 2.8 | T17: =HLOOKUP($T$1,$I$4:$Q$19,$Y17) -> 0.011655837 | U17: =HLOOKUP($T$1,$I$20:$Q$35,$Y17) -> 0.0096717866 | V17: =HLOOKUP($T$1,$I$36:$Q$51,$Y17) -> 0.007983742 | W17: =HLOOKUP($T$1,$I$52:$Q$67,$Y17) -> 0.0066398896 | X17: =HLOOKUP($T$1,$I$68:$Q$83,$Y17) -> 0.0055170935 | Y17: 15
A18: 0.5 | B18: 7 | C18: 0.8 | D18: 1 | E18: 68 | F18: =D18/E18 -> 0.014705882 | H18: 2.8 | I18: =AVERAGE(F77:F82) -> 0.011655837 | J18: 2.8 | K18: =AVERAGE(F413:F418) -> 0.01683705 | L18: 2.8 | M18: =AVERAGE(F749:F754) -> 0.022419826 | N18: 2.8 | O18: =AVERAGE(F1085:F1090) -> 0.033564992 | P18: 2.8 | Q18: =AVERAGE(F1421:F1426) -> 0.044815026 | S18: 3 | T18: =HLOOKUP($T$1,$I$4:$Q$19,$Y18) -> 0.011460778 | U18: =HLOOKUP($T$1,$I$20:$Q$35,$Y18) -> 0.0094882483 | V18: =HLOOKUP($T$1,$I$36:$Q$51,$Y18) -> 0.0078496824 | W18: =HLOOKUP($T$1,$I$52:$Q$67,$Y18) -> 0.0065191676 | X18: =HLOOKUP($T$1,$I$68:$Q$83,$Y18) -> 0.0054347826 | Y18: 16
A19: 0.5 | B19: 7 | C19: 0.8 | D19: 1.5 | E19: 103 | F19: =D19/E19 -> 0.014563107 | H19: 3 | I19: =AVERAGE(F83:F88) -> 0.011460778 | J19: 3 | K19: =AVERAGE(F419:F424) -> 0.016500573 | L19: 3 | M19: =AVERAGE(F755:F760) -> 0.021837175 | N19: 3 | O19: =AVERAGE(F1091:F1096) -> 0.032987336 | P19: 3 | Q19: =AVERAGE(F1427:F1432) -> 0.044245366
A20: 0.5 | B20: 7 | C20: 0.8 | D20: 2 | E20: 137 | F20: =D20/E20 -> 0.01459854 | G20: temp: | I20: 0.5 | K20: 5 | M20: 10 | O20: 15 | Q20: 20
A21: 0.5 | B21: 7 | C21: 0.8 | D21: 2.5 | E21: 171 | F21: =D21/E21 -> 0.014619883 | G21: pH: | I21: 7.5 | K21: 7.5 | M21: 7.5 | O21: 7.5 | Q21: 7.5
A22: 0.5 | B22: 7 | C22: 0.8 | D22: 3 | E22: 205 | F22: =D22/E22 -> 0.014634146 | H22: 0.4 | I22: =AVERAGE(F89:F94) -> 0.012617665 | J22: 0.4 | K22: =AVERAGE(F425:F430) -> 0.018052917 | L22: 0.4 | M22: =AVERAGE(F761:F766) -> 0.023927236 | N22: 0.4 | O22: =AVERAGE(F1097:F1102) -> 0.035980493 | P22: 0.4 | Q22: =AVERAGE(F1433:F1438) -> 0.048541775
A23: 0.5 | B23: 7 | C23: 1 | D23: 0.5 | E23: 35 | F23: =D23/E23 -> 0.014285714 | H23: 0.6 | I23: =AVERAGE(F95:F100) -> 0.012532289 | J23: 0.6 | K23: =AVERAGE(F431:F436) -> 0.017466223 | L23: 0.6 | M23: =AVERAGE(F767:F772) -> 0.023472373 | N23: 0.6 | O23: =AVERAGE(F1103:F1108) -> 0.034962405 | P23: 0.6 | Q23: =AVERAGE(F1439:F1444) -> 0.046750839
A24: 0.5 | B24: 7 | C24: 1 | D24: 1 | E24: 70 | F24: =D24/E24 -> 0.014285714 | H24: 0.8 | I24: =AVERAGE(F101:F106) -> 0.012195122 | J24: 0.8 | K24: =AVERAGE(F437:F442) -> 0.017148063 | L24: 0.8 | M24: =AVERAGE(F773:F778) -> 0.022834478 | N24: 0.8 | O24: =AVERAGE(F1109:F1114) -> 0.034023798 | P24: 0.8 | Q24: =AVERAGE(F1445:F1450) -> 0.045454545
A25: 0.5 | B25: 7 | C25: 1 | D25: 1.5 | E25: 105 | F25: =D25/E25 -> 0.014285714 | H25: 1 | I25: =AVERAGE(F107:F112) -> 0.011860153 | J25: 1 | K25: =AVERAGE(F443:F448) -> 0.01672417 | L25: 1 | M25: =AVERAGE(F779:F784) -> 0.022419826 | N25: 1 | O25: =AVERAGE(F1115:F1120) -> 0.033333333 | P25: 1 | Q25: =AVERAGE(F1451:F1456) -> 0.044815026
A26: 0.5 | B26: 7 | C26: 1 | D26: 2 | E26: 140 | F26: =D26/E26 -> 0.014285714 | H26: 1.2 | I26: =AVERAGE(F113:F118) -> 0.011585342 | J26: 1.2 | K26: =AVERAGE(F449:F454) -> 0.016325596 | L26: 1.2 | M26: =AVERAGE(F785:F790) -> 0.021837175 | N26: 1.2 | O26: =AVERAGE(F1121:F1126) -> 0.032677201 | P26: 1.2 | Q26: =AVERAGE(F1457:F1462) -> 0.04301034
A27: 0.5 | B27: 7 | C27: 1 | D27: 2.5 | E27: 175 | F27: =D27/E27 -> 0.014285714 | H27: 1.4 | I27: =AVERAGE(F119:F124) -> 0.011286113 | J27: 1.4 | K27: =AVERAGE(F455:F460) -> 0.016047322 | L27: 1.4 | M27: =AVERAGE(F791:F796) -> 0.021457628 | N27: 1.4 | O27: =AVERAGE(F1127:F1132) -> 0.031855861 | P27: 1.4 | Q27: =AVERAGE(F1463:F1468) -> 0.042752642
A28: 0.5 | B28: 7 | C28: 1 | D28: 3 | E28: 210 | F28: =D28/E28 -> 0.014285714 | H28: 1.6 | I28: =AVERAGE(F125:F130) -> 0.010958403 | J28: 1.6 | K28: =AVERAGE(F461:F466) -> 0.015625 | L28: 1.6 | M28: =AVERAGE(F797:F802) -> 0.020833333 | N28: 1.6 | O28: =AVERAGE(F1133:F1138) -> 0.03125 | P28: 1.6 | Q28: =AVERAGE(F1469:F1474) -> 0.041666667
A29: 0.5 | B29: 7 | C29: 1.2 | D29: 0.5 | E29: 36 | F29: =D29/E29 -> 0.013888889 | H29: 1.8 | I29: =AVERAGE(F131:F136) -> 0.010723377 | J29: 1.8 | K29: =AVERAGE(F467:F472) -> 0.015292162 | L29: 1.8 | M29: =AVERAGE(F803:F808) -> 0.020303327 | N29: 1.8 | O29: =AVERAGE(F1139:F1144) -> 0.030672426 | P29: 1.8 | Q29: =AVERAGE(F1475:F1480) -> 0.040647776
A30: 0.5 | B30: 7 | C30: 1.2 | D30: 1 | E30: 72 | F30: =D30/E30 -> 0.013888889 | H30: 2 | I30: =AVERAGE(F137:F142) -> 0.010482902 | J30: 2 | K30: =AVERAGE(F473:F478) -> 0.01501409 | L30: 2 | M30: =AVERAGE(F809:F814) -> 0.02 | N30: 2 | O30: =AVERAGE(F1145:F1150) -> 0.029947671 | P30: 2 | Q30: =AVERAGE(F1481:F1486) -> 0.03960296
A31: 0.5 | B31: 7 | C31: 1.2 | D31: 1.5 | E31: 108 | F31: =D31/E31 -> 0.013888889 | H31: 2.2 | I31: =AVERAGE(F143:F148) -> 0.010075132 | J31: 2.2 | K31: =AVERAGE(F479:F484) -> 0.014705882 | L31: 2.2 | M31: =AVERAGE(F815:F820) -> 0.019511011 | N31: 2.2 | O31: =AVERAGE(F1151:F1156) -> 0.029411765 | P31: 2.2 | Q31: =AVERAGE(F1487:F1492) -> 0.03877064
A32: 0.5 | B32: 7 | C32: 1.2 | D32: 2 | E32: 143 | F32: =D32/E32 -> 0.013986014 | H32: 2.4 | I32: =AVERAGE(F149:F154) -> 0.010061022 | J32: 2.4 | K32: =AVERAGE(F485:F490) -> 0.014327919 | L32: 2.4 | M32: =AVERAGE(F821:F826) -> 0.019114792 | N32: 2.4 | O32: =AVERAGE(F1157:F1162) -> 0.028367174 | P32: 2.4 | Q32: =AVERAGE(F1493:F1498) -> 0.038461538
A33: 0.5 | B33: 7 | C33: 1.2 | D33: 2.5 | E33: 179 | F33: =D33/E33 -> 0.01396648 | H33: 2.6 | I33: =AVERAGE(F155:F160) -> 0.0098625656 | J33: 2.6 | K33: =AVERAGE(F491:F496) -> 0.014034341 | L33: 2.6 | M33: =AVERAGE(F827:F832) -> 0.018729171 | N33: 2.6 | O33: =AVERAGE(F1163:F1168) -> 0.02793827 | P33: 2.6 | Q33: =AVERAGE(F1499:F1504) -> 0.03759131
A34: 0.5 | B34: 7 | C34: 1.2 | D34: 3 | E34: 215 | F34: =D34/E34 -> 0.013953488 | H34: 2.8 | I34: =AVERAGE(F161:F166) -> 0.0096717866 | J34: 2.8 | K34: =AVERAGE(F497:F502) -> 0.013828231 | L34: 2.8 | M34: =AVERAGE(F833:F838) -> 0.018410934 | N34: 2.8 | O34: =AVERAGE(F1169:F1174) -> 0.027536834 | P34: 2.8 | Q34: =AVERAGE(F1505:F1510) -> 0.036695911
A35: 0.5 | B35: 7 | C35: 1.4 | D35: 0.5 | E35: 37 | F35: =D35/E35 -> 0.013513514 | H35: 3 | I35: =AVERAGE(F167:F172) -> 0.0094882483 | J35: 3 | K35: =AVERAGE(F503:F508) -> 0.013551267 | L35: 3 | M35: =AVERAGE(F839:F844) -> 0.018052917 | N35: 3 | O35: =AVERAGE(F1175:F1180) -> 0.026844051 | P35: 3 | Q35: =AVERAGE(F1511:F1516) -> 0.035980493
A36: 0.5 | B36: 7 | C36: 1.4 | D36: 1 | E36: 74 | F36: =D36/E36 -> 0.013513514 | G36: temp: | I36: 0.5 | K36: 5 | M36: 10 | O36: 15 | Q36: 20
A37: 0.5 | B37: 7 | C37: 1.4 | D37: 1.5 | E37: 111 | F37: =D37/E37 -> 0.013513514 | G37: pH: | I37: 8 | K37: 8 | M37: 8 | O37: 8 | Q37: 8
A38: 0.5 | B38: 7 | C38: 1.4 | D38: 2 | E38: 147 | F38: =D38/E38 -> 0.013605442 | H38: 0.4 | I38: =AVERAGE(F173:F178) -> 0.010832357 | J38: 0.4 | K38: =AVERAGE(F509:F514) -> 0.015151515 | L38: 0.4 | M38: =AVERAGE(F845:F850) -> 0.020082923 | N38: 0.4 | O38: =AVERAGE(F1181:F1186) -> 0.030073556 | P38: 0.4 | Q38: =AVERAGE(F1517:F1522) -> 0.040647776
A39: 0.5 | B39: 7 | C39: 1.4 | D39: 2.5 | E39: 184 | F39: =D39/E39 -> 0.013586957 | H39: 0.6 | I39: =AVERAGE(F179:F184) -> 0.010482902 | J39: 0.6 | K39: =AVERAGE(F515:F520) -> 0.014705882 | L39: 0.6 | M39: =AVERAGE(F851:F856) -> 0.019511011 | N39: 0.6 | O39: =AVERAGE(F1187:F1192) -> 0.029411765 | P39: 0.6 | Q39: =AVERAGE(F1523:F1528) -> 0.03877064
A40: 0.5 | B40: 7 | C40: 1.4 | D40: 3 | E40: 201 | F40: =D40/E40 -> 0.014925373 | H40: 0.8 | I40: =AVERAGE(F185:F190) -> 0.010171279 | J40: 0.8 | K40: =AVERAGE(F521:F526) -> 0.014285714 | L40: 0.8 | M40: =AVERAGE(F857:F862) -> 0.019010065 | N40: 0.8 | O40: =AVERAGE(F1193:F1198) -> 0.028367174 | P40: 0.8 | Q40: =AVERAGE(F1529:F1534) -> 0.038002066
...

Sheet Virus CT
A1: CT Tables
A4: Viruses | H4: Average K values for every Temp
A5: Temperature | B5: pH | C5: Log Inactivation | D5: CT | E5: k | H5: Temperature | I5: k
A6: 0.5 | B6: 6-9 | C6: 2 | D6: 6 | E6: =C6/D6 -> 0.33333333 | H6: 0.5 | I6: =AVERAGE(E6:E8) -> 0.33333333
A7: 0.5 | B7: 6-9 | C7: 3 | D7: 9 | E7: =C7/D7 -> 0.33333333 | H7: 5 | I7: =AVERAGE(E9:E11) -> 0.5
A8: 0.5 | B8: 6-9 | C8: 4 | D8: 12 | E8: =C8/D8 -> 0.33333333 | H8: 10 | I8: =AVERAGE(E12:E14) -> 0.69444444
A9: 5 | B9: 6-9 | C9: 2 | D9: 4 | E9: =C9/D9 -> 0.5 | H9: 15 | I9: =AVERAGE(E15:E17) -> 1
A10: 5 | B10: 6-9 | C10: 3 | D10: 6 | E10: =C10/D10 -> 0.5 | H10: 20 | I10: =AVERAGE(E18:E20) -> 1.6111111
A11: 5 | B11: 6-9 | C11: 4 | D11: 8 | E11: =C11/D11 -> 0.5 | H11: 25 | I11: =AVERAGE(E21:E23) -> 2.3333333
A12: 10 | B12: 6-9 | C12: 2 | D12: 3 | E12: =C12/D12 -> 0.66666667
A13: 10 | B13: 6-9 | C13: 3 | D13: 4 | E13: =C13/D13 -> 0.75
A14: 10 | B14: 6-9 | C14: 4 | D14: 6 | E14: =C14/D14 -> 0.66666667
A15: 15 | B15: 6-9 | C15: 2 | D15: 2 | E15: =C15/D15 -> 1
A16: 15 | B16: 6-9 | C16: 3 | D16: 3 | E16: =C16/D16 -> 1
A17: 15 | B17: 6-9 | C17: 4 | D17: 4 | E17: =C17/D17 -> 1
A18: 20 | B18: 6-9 | C18: 2 | D18: 1 | E18: =C18/D18 -> 2
A19: 20 | B19: 6-9 | C19: 3 | D19: 2 | E19: =C19/D19 -> 1.5
A20: 20 | B20: 6-9 | C20: 4 | D20: 3 | E20: =C20/D20 -> 1.3333333
A21: 25 | B21: 6-9 | C21: 2 | D21: 1 | E21: =C21/D21 -> 2
A22: 25 | B22: 6-9 | C22: 3 | D22: 1 | E22: =C22/D22 -> 3
A23: 25 | B23: 6-9 | C23: 4 | D23: 2 | E23: =C23/D23 -> 2
